Traceback (most recent call last):
  File "/home/orestas41/miniconda3/envs/mlflow-2607edbc4612998530e14928de78596a3fc9fc6f/lib/python3.10/site-packages/pandas/core/indexes/base.py", line 3621, in get_loc
    return self._engine.get_loc(casted_key)
  File "pandas/_libs/index.pyx", line 136, in pandas._libs.index.IndexEngine.get_loc
  File "pandas/_libs/index.pyx", line 142, in pandas._libs.index.IndexEngine.get_loc
TypeError: '['Winner']' is an invalid key
During handling of the above exception, another exception occurred:
Traceback (most recent call last):
  File "/home/orestas41/project-FootballPredict/lithuanian-football-league-predictor/training_validation/run.py", line 154, in <module>
    go(args)
  File "/home/orestas41/project-FootballPredict/lithuanian-football-league-predictor/training_validation/run.py", line 50, in go
    y = X.pop(['Winner'])
  File "/home/orestas41/miniconda3/envs/mlflow-2607edbc4612998530e14928de78596a3fc9fc6f/lib/python3.10/site-packages/pandas/core/frame.py", line 5264, in pop
    return super().pop(item=item)
  File "/home/orestas41/miniconda3/envs/mlflow-2607edbc4612998530e14928de78596a3fc9fc6f/lib/python3.10/site-packages/pandas/core/generic.py", line 874, in pop
    del self[item]
  File "/home/orestas41/miniconda3/envs/mlflow-2607edbc4612998530e14928de78596a3fc9fc6f/lib/python3.10/site-packages/pandas/core/generic.py", line 4060, in __delitem__
    loc = self.axes[-1].get_loc(key)
  File "/home/orestas41/miniconda3/envs/mlflow-2607edbc4612998530e14928de78596a3fc9fc6f/lib/python3.10/site-packages/pandas/core/indexes/base.py", line 3628, in get_loc
    self._check_indexing_error(key)
  File "/home/orestas41/miniconda3/envs/mlflow-2607edbc4612998530e14928de78596a3fc9fc6f/lib/python3.10/site-packages/pandas/core/indexes/base.py", line 5637, in _check_indexing_error
    raise InvalidIndexError(key)
pandas.errors.InvalidIndexError: ['Winner']