
[34m[1mwandb[39m[22m:   4 of 4 files downloaded.
Traceback (most recent call last):
  File "/home/orestas41/miniconda3/envs/mlflow-0f3cd73a3642fabcbe7a5d3994aef20e5536143a/lib/python3.10/site-packages/pandas/core/indexes/base.py", line 3621, in get_loc
    return self._engine.get_loc(casted_key)
  File "pandas/_libs/index.pyx", line 136, in pandas._libs.index.IndexEngine.get_loc
  File "pandas/_libs/index.pyx", line 142, in pandas._libs.index.IndexEngine.get_loc
TypeError: '['homeResult', 'awayResult', 'Winner']' is an invalid key
During handling of the above exception, another exception occurred:
Traceback (most recent call last):
  File "/home/orestas41/project-FootballPredict/lithuanian-football-league-predictor/test_model/run.py", line 114, in <module>
    go(args)
  File "/home/orestas41/project-FootballPredict/lithuanian-football-league-predictor/test_model/run.py", line 43, in go
    y_test = X_test.pop(["homeResult", "awayResult", "Winner"])
  File "/home/orestas41/miniconda3/envs/mlflow-0f3cd73a3642fabcbe7a5d3994aef20e5536143a/lib/python3.10/site-packages/pandas/core/frame.py", line 5264, in pop
    return super().pop(item=item)
  File "/home/orestas41/miniconda3/envs/mlflow-0f3cd73a3642fabcbe7a5d3994aef20e5536143a/lib/python3.10/site-packages/pandas/core/generic.py", line 874, in pop
    del self[item]
  File "/home/orestas41/miniconda3/envs/mlflow-0f3cd73a3642fabcbe7a5d3994aef20e5536143a/lib/python3.10/site-packages/pandas/core/generic.py", line 4060, in __delitem__
    loc = self.axes[-1].get_loc(key)
  File "/home/orestas41/miniconda3/envs/mlflow-0f3cd73a3642fabcbe7a5d3994aef20e5536143a/lib/python3.10/site-packages/pandas/core/indexes/base.py", line 3628, in get_loc
    self._check_indexing_error(key)
  File "/home/orestas41/miniconda3/envs/mlflow-0f3cd73a3642fabcbe7a5d3994aef20e5536143a/lib/python3.10/site-packages/pandas/core/indexes/base.py", line 5637, in _check_indexing_error
    raise InvalidIndexError(key)
pandas.errors.InvalidIndexError: ['homeResult', 'awayResult', 'Winner']