Traceback (most recent call last):
  File "/home/orestas41/project-FootballPredict/lithuanian-football-league-predictor/training_validation/run.py", line 148, in <module>
    go(args)
  File "/home/orestas41/project-FootballPredict/lithuanian-football-league-predictor/training_validation/run.py", line 50, in go
    y = X.pop(['homeResult', 'awayResutl', 'Winner'])
  File "/home/orestas41/miniconda3/envs/mlflow-2607edbc4612998530e14928de78596a3fc9fc6f/lib/python3.10/site-packages/pandas/core/frame.py", line 5264, in pop
    return super().pop(item=item)
  File "/home/orestas41/miniconda3/envs/mlflow-2607edbc4612998530e14928de78596a3fc9fc6f/lib/python3.10/site-packages/pandas/core/generic.py", line 873, in pop
    result = self[item]
  File "/home/orestas41/miniconda3/envs/mlflow-2607edbc4612998530e14928de78596a3fc9fc6f/lib/python3.10/site-packages/pandas/core/frame.py", line 3511, in __getitem__
    indexer = self.columns._get_indexer_strict(key, "columns")[1]
  File "/home/orestas41/miniconda3/envs/mlflow-2607edbc4612998530e14928de78596a3fc9fc6f/lib/python3.10/site-packages/pandas/core/indexes/base.py", line 5782, in _get_indexer_strict
    self._raise_if_missing(keyarr, indexer, axis_name)
  File "/home/orestas41/miniconda3/envs/mlflow-2607edbc4612998530e14928de78596a3fc9fc6f/lib/python3.10/site-packages/pandas/core/indexes/base.py", line 5845, in _raise_if_missing
    raise KeyError(f"{not_found} not in index")
KeyError: "['awayResutl'] not in index"