Traceback (most recent call last):
  File "/home/orestas41/miniconda3/envs/mlflow-2607edbc4612998530e14928de78596a3fc9fc6f/lib/python3.10/site-packages/pandas/core/indexes/base.py", line 3621, in get_loc
    return self._engine.get_loc(casted_key)
  File "pandas/_libs/index.pyx", line 136, in pandas._libs.index.IndexEngine.get_loc
  File "pandas/_libs/index.pyx", line 163, in pandas._libs.index.IndexEngine.get_loc
  File "pandas/_libs/hashtable_class_helper.pxi", line 5198, in pandas._libs.hashtable.PyObjectHashTable.get_item
  File "pandas/_libs/hashtable_class_helper.pxi", line 5206, in pandas._libs.hashtable.PyObjectHashTable.get_item
KeyError: ('homeResult', 'awayResult', 'Winner')
The above exception was the direct cause of the following exception:
Traceback (most recent call last):
  File "/home/orestas41/project-FootballPredict/lithuanian-football-league-predictor/training_validation/run.py", line 156, in <module>
    go(args)
  File "/home/orestas41/project-FootballPredict/lithuanian-football-league-predictor/training_validation/run.py", line 53, in go
    y = X["homeResult", "awayResult", "Winner"]
  File "/home/orestas41/miniconda3/envs/mlflow-2607edbc4612998530e14928de78596a3fc9fc6f/lib/python3.10/site-packages/pandas/core/frame.py", line 3505, in __getitem__
    indexer = self.columns.get_loc(key)
  File "/home/orestas41/miniconda3/envs/mlflow-2607edbc4612998530e14928de78596a3fc9fc6f/lib/python3.10/site-packages/pandas/core/indexes/base.py", line 3623, in get_loc
    raise KeyError(key) from err
KeyError: ('homeResult', 'awayResult', 'Winner')