Traceback (most recent call last):
  File "/home/orestas41/project-FootballPredict/lithuanian-football-league-predictor/tour_eval_pred/run.py", line 187, in <module>
    go(args)
  File "/home/orestas41/project-FootballPredict/lithuanian-football-league-predictor/tour_eval_pred/run.py", line 98, in go
    prev_preds.columns = ['Prediction']
  File "/home/orestas41/miniconda3/envs/mlflow-179e34a71618ccb1126551092a7decef1effd393/lib/python3.10/site-packages/pandas/core/generic.py", line 5596, in __setattr__
    return object.__setattr__(self, name, value)
  File "pandas/_libs/properties.pyx", line 70, in pandas._libs.properties.AxisProperty.__set__
  File "/home/orestas41/miniconda3/envs/mlflow-179e34a71618ccb1126551092a7decef1effd393/lib/python3.10/site-packages/pandas/core/generic.py", line 769, in _set_axis
    self._mgr.set_axis(axis, labels)
  File "/home/orestas41/miniconda3/envs/mlflow-179e34a71618ccb1126551092a7decef1effd393/lib/python3.10/site-packages/pandas/core/internals/managers.py", line 214, in set_axis
    self._validate_set_axis(axis, new_labels)
  File "/home/orestas41/miniconda3/envs/mlflow-179e34a71618ccb1126551092a7decef1effd393/lib/python3.10/site-packages/pandas/core/internals/base.py", line 69, in _validate_set_axis
    raise ValueError(
ValueError: Length mismatch: Expected axis has 4 elements, new values have 1 elements