     0
0  1.0
1  0.5
2  0.5
3  0.0
Traceback (most recent call last):
  File "/home/orestas41/miniconda3/envs/mlflow-179e34a71618ccb1126551092a7decef1effd393/lib/python3.10/site-packages/pandas/core/indexes/base.py", line 3621, in get_loc
    return self._engine.get_loc(casted_key)
  File "pandas/_libs/index.pyx", line 136, in pandas._libs.index.IndexEngine.get_loc
  File "pandas/_libs/index.pyx", line 144, in pandas._libs.index.IndexEngine.get_loc
  File "pandas/_libs/index_class_helper.pxi", line 41, in pandas._libs.index.Int64Engine._check_type
KeyError: '0'
The above exception was the direct cause of the following exception:
Traceback (most recent call last):
  File "/home/orestas41/project-FootballPredict/lithuanian-football-league-predictor/tour_eval_pred/run.py", line 185, in <module>
    go(args)
  File "/home/orestas41/project-FootballPredict/lithuanian-football-league-predictor/tour_eval_pred/run.py", line 100, in go
    df['Prediction'] = prev_preds['0']
  File "/home/orestas41/miniconda3/envs/mlflow-179e34a71618ccb1126551092a7decef1effd393/lib/python3.10/site-packages/pandas/core/frame.py", line 3505, in __getitem__
    indexer = self.columns.get_loc(key)
  File "/home/orestas41/miniconda3/envs/mlflow-179e34a71618ccb1126551092a7decef1effd393/lib/python3.10/site-packages/pandas/core/indexes/base.py", line 3623, in get_loc
    raise KeyError(key) from err
KeyError: '0'